[2025-06-04 22:29:23 +0800] [2328027] [INFO] Starting gunicorn 20.1.0
[2025-06-04 22:29:23 +0800] [2328027] [INFO] Listening at: http://0.0.0.0:5000 (2328027)
[2025-06-04 22:29:23 +0800] [2328027] [INFO] Using worker: sync
[2025-06-04 22:29:23 +0800] [2328034] [INFO] Booting worker with pid: 2328034
[2025-06-04 22:29:23 +0800] [2328035] [INFO] Booting worker with pid: 2328035
[2025-06-04 22:29:23 +0800] [2328034] [ERROR] Exception in worker process
Traceback (most recent call last):
  File "/usr/lib/python3/dist-packages/gunicorn/arbiter.py", line 589, in spawn_worker
    worker.init_process()
  File "/usr/lib/python3/dist-packages/gunicorn/workers/base.py", line 134, in init_process
    self.load_wsgi()
  File "/usr/lib/python3/dist-packages/gunicorn/workers/base.py", line 146, in load_wsgi
    self.wsgi = self.app.wsgi()
  File "/usr/lib/python3/dist-packages/gunicorn/app/base.py", line 67, in wsgi
    self.callable = self.load()
  File "/usr/lib/python3/dist-packages/gunicorn/app/wsgiapp.py", line 58, in load
    return self.load_wsgiapp()
  File "/usr/lib/python3/dist-packages/gunicorn/app/wsgiapp.py", line 48, in load_wsgiapp
    return util.import_app(self.app_uri)
  File "/usr/lib/python3/dist-packages/gunicorn/util.py", line 384, in import_app
    mod = importlib.import_module(module)
  File "/usr/lib/python3.10/importlib/__init__.py", line 126, in import_module
    return _bootstrap._gcd_import(name[level:], package, level)
  File "<frozen importlib._bootstrap>", line 1050, in _gcd_import
  File "<frozen importlib._bootstrap>", line 1027, in _find_and_load
  File "<frozen importlib._bootstrap>", line 1006, in _find_and_load_unlocked
  File "<frozen importlib._bootstrap>", line 688, in _load_unlocked
  File "<frozen importlib._bootstrap_external>", line 883, in exec_module
  File "<frozen importlib._bootstrap>", line 241, in _call_with_frames_removed
  File "/var/www/eve_service/eve_service/app.py", line 1, in <module>
    from flask import Flask, render_template, jsonify, request, send_from_directory
ModuleNotFoundError: No module named 'flask'
[2025-06-04 22:29:23 +0800] [2328034] [INFO] Worker exiting (pid: 2328034)
[2025-06-04 22:29:23 +0800] [2328035] [ERROR] Exception in worker process
Traceback (most recent call last):
  File "/usr/lib/python3/dist-packages/gunicorn/arbiter.py", line 589, in spawn_worker
    worker.init_process()
  File "/usr/lib/python3/dist-packages/gunicorn/workers/base.py", line 134, in init_process
    self.load_wsgi()
  File "/usr/lib/python3/dist-packages/gunicorn/workers/base.py", line 146, in load_wsgi
    self.wsgi = self.app.wsgi()
  File "/usr/lib/python3/dist-packages/gunicorn/app/base.py", line 67, in wsgi
    self.callable = self.load()
  File "/usr/lib/python3/dist-packages/gunicorn/app/wsgiapp.py", line 58, in load
    return self.load_wsgiapp()
  File "/usr/lib/python3/dist-packages/gunicorn/app/wsgiapp.py", line 48, in load_wsgiapp
    return util.import_app(self.app_uri)
  File "/usr/lib/python3/dist-packages/gunicorn/util.py", line 384, in import_app
    mod = importlib.import_module(module)
  File "/usr/lib/python3.10/importlib/__init__.py", line 126, in import_module
    return _bootstrap._gcd_import(name[level:], package, level)
  File "<frozen importlib._bootstrap>", line 1050, in _gcd_import
  File "<frozen importlib._bootstrap>", line 1027, in _find_and_load
  File "<frozen importlib._bootstrap>", line 1006, in _find_and_load_unlocked
  File "<frozen importlib._bootstrap>", line 688, in _load_unlocked
  File "<frozen importlib._bootstrap_external>", line 883, in exec_module
  File "<frozen importlib._bootstrap>", line 241, in _call_with_frames_removed
  File "/var/www/eve_service/eve_service/app.py", line 1, in <module>
    from flask import Flask, render_template, jsonify, request, send_from_directory
ModuleNotFoundError: No module named 'flask'
[2025-06-04 22:29:23 +0800] [2328035] [INFO] Worker exiting (pid: 2328035)
[2025-06-04 22:30:16 +0800] [2328988] [INFO] Starting gunicorn 20.1.0
[2025-06-04 22:30:16 +0800] [2328988] [INFO] Listening at: http://0.0.0.0:5000 (2328988)
[2025-06-04 22:30:16 +0800] [2328988] [INFO] Using worker: sync
[2025-06-04 22:30:16 +0800] [2328993] [INFO] Booting worker with pid: 2328993
[2025-06-04 22:30:16 +0800] [2328993] [ERROR] Exception in worker process
Traceback (most recent call last):
  File "/usr/lib/python3/dist-packages/gunicorn/arbiter.py", line 589, in spawn_worker
    worker.init_process()
  File "/usr/lib/python3/dist-packages/gunicorn/workers/base.py", line 134, in init_process
    self.load_wsgi()
  File "/usr/lib/python3/dist-packages/gunicorn/workers/base.py", line 146, in load_wsgi
    self.wsgi = self.app.wsgi()
  File "/usr/lib/python3/dist-packages/gunicorn/app/base.py", line 67, in wsgi
    self.callable = self.load()
  File "/usr/lib/python3/dist-packages/gunicorn/app/wsgiapp.py", line 58, in load
    return self.load_wsgiapp()
  File "/usr/lib/python3/dist-packages/gunicorn/app/wsgiapp.py", line 48, in load_wsgiapp
    return util.import_app(self.app_uri)
  File "/usr/lib/python3/dist-packages/gunicorn/util.py", line 384, in import_app
    mod = importlib.import_module(module)
  File "/usr/lib/python3.10/importlib/__init__.py", line 126, in import_module
    return _bootstrap._gcd_import(name[level:], package, level)
  File "<frozen importlib._bootstrap>", line 1050, in _gcd_import
  File "<frozen importlib._bootstrap>", line 1027, in _find_and_load
  File "<frozen importlib._bootstrap>", line 1006, in _find_and_load_unlocked
  File "<frozen importlib._bootstrap>", line 688, in _load_unlocked
  File "<frozen importlib._bootstrap_external>", line 883, in exec_module
  File "<frozen importlib._bootstrap>", line 241, in _call_with_frames_removed
  File "/var/www/eve_service/eve_service/app.py", line 1, in <module>
    from flask import Flask, render_template, jsonify, request, send_from_directory
ModuleNotFoundError: No module named 'flask'
[2025-06-04 22:30:16 +0800] [2328993] [INFO] Worker exiting (pid: 2328993)
[2025-06-04 22:30:16 +0800] [2328988] [INFO] Shutting down: Master
[2025-06-04 22:30:16 +0800] [2328988] [INFO] Reason: Worker failed to boot.
